package Javacore.Oexception.runtime.test;

public class RuntimeExceptionTest03 {
    public static void main(String[] args) {
        System.out.println(abreConexao());
    }

    private static String abreConexao() {
        int[] valores = new int[2];
        valores[0] = 2;
        valores[1] = 2 ;
        try{
            System.out.println("Abrindo arquivo");
            System.out.println("Escrevendo dados no arquivo");
            System.out.println("Valor "+valores[5]);
            System.out.println();
            return "COnex√£o aberta";
        }catch(Exception e){
            e.printStackTrace();
        } finally {
            System.out.println("Fechando recurso liberado pelo SO");
        }
        return null;
    }

    private static void abreConexao2() {
        try{
            System.out.println("Abrindo arquivo");
            System.out.println("Escrevendo dados no arquivo");
            throw  new RuntimeException();
        } finally {
            System.out.println("Fechando recurso liberado pelo SO");
        }
    }
}
